[32m2025-10-26 09:37:03 +0100[0m - dagster - [34mDEBUG[0m - job_ads_etl_pipeline - 2e8ee079-6de4-4115-89f4-d9153fefa99a - 6494 - LOGS_CAPTURED - Started capturing logs in process (pid: 6494).
[32m2025-10-26 09:37:03 +0100[0m - dagster - [34mDEBUG[0m - job_ads_etl_pipeline - 2e8ee079-6de4-4115-89f4-d9153fefa99a - 6494 - transform_data_op - STEP_START - Started execution of step "transform_data_op".
[32m2025-10-26 09:37:03 +0100[0m - dagster - [34mDEBUG[0m - job_ads_etl_pipeline - 2e8ee079-6de4-4115-89f4-d9153fefa99a - transform_data_op - Loading file from: /Users/pete/Desktop/DataFlow/.tmp_dagster_home_afr9jb1y/storage/2e8ee079-6de4-4115-89f4-d9153fefa99a/extract_and_load_op/result using PickledObjectFilesystemIOManager...
[32m2025-10-26 09:37:03 +0100[0m - dagster - [34mDEBUG[0m - job_ads_etl_pipeline - 2e8ee079-6de4-4115-89f4-d9153fefa99a - 6494 - transform_data_op - LOADED_INPUT - Loaded input "start_signal" using input manager "io_manager", from output "result" of step "extract_and_load_op"
[32m2025-10-26 09:37:03 +0100[0m - dagster - [34mDEBUG[0m - job_ads_etl_pipeline - 2e8ee079-6de4-4115-89f4-d9153fefa99a - 6494 - transform_data_op - STEP_INPUT - Got input "start_signal" of type "Any". (Type check passed).
[32m2025-10-26 09:37:05 +0100[0m - dagster - [34mERROR[0m - [31mjob_ads_etl_pipeline - 2e8ee079-6de4-4115-89f4-d9153fefa99a - 6494 - transform_data_op - STEP_FAILURE - Execution of step "transform_data_op" failed.

dagster._core.errors.DagsterExecutionStepExecutionError: Error occurred while executing op "transform_data_op"::

subprocess.CalledProcessError: Command '['dbt', 'run', '--project-dir', 'job_ads_dbt']' returned non-zero exit status 2.

Stack Trace:
  File "/Users/pete/Desktop/DataFlow/.venv/lib/python3.12/site-packages/dagster/_core/execution/plan/utils.py", line 57, in op_execution_error_boundary
    yield
  File "/Users/pete/Desktop/DataFlow/.venv/lib/python3.12/site-packages/dagster/_utils/__init__.py", line 392, in iterate_with_context
    next_output = next(iterator)
                  ^^^^^^^^^^^^^^
  File "/Users/pete/Desktop/DataFlow/.venv/lib/python3.12/site-packages/dagster/_core/execution/plan/compute_generator.py", line 137, in _coerce_op_compute_fn_to_iterator
    result = invoke_compute_fn(
             ^^^^^^^^^^^^^^^^^^
  File "/Users/pete/Desktop/DataFlow/.venv/lib/python3.12/site-packages/dagster/_core/execution/plan/compute_generator.py", line 117, in invoke_compute_fn
    return fn(context, **args_to_pass) if context_arg_provided else fn(**args_to_pass)
                                                                    ^^^^^^^^^^^^^^^^^^
  File "/Users/pete/Desktop/DataFlow/defs.py", line 24, in transform_data
    subprocess.run(
  File "/Users/pete/.pyenv/versions/3.12.6/lib/python3.12/subprocess.py", line 571, in run
    raise CalledProcessError(retcode, process.args,
[0m
